Workbook

Sheet 估值比較
A1: 智邦（2345）估值總覽 現價 NT$1,900（2026-10-01 收盤）
A3: 方法 | B3: 價值 (NT$) | C3: 對現價 | D3: 備註
A4: Kevin 情境 A（主） | B4: =Kevin模型!B43 | C4: =B4/Kevin模型!B22-1 | D4: 1–8月×12/8、H1 帳面淨利率 11.70%
A5: Kevin 情境 B | B5: =Kevin模型!C43 | C5: =B5/Kevin模型!B22-1 | D5: 近兩月均 401.7 億 × 剩餘 4 個月、Q2 淨利率 11.56%
A6: 雙法 PE band Low | B6: =Kevin模型!B47 | C6: =B6/Kevin模型!B22-1 | D6: Q×0.8
A7: 雙法 PE band Mid | B7: =Kevin模型!B48 | C7: =B7/Kevin模型!B22-1 | D7: (P+Q)/2
A8: 雙法 PE band High | B8: =Kevin模型!B49 | C8: =B8/Kevin模型!B22-1 | D8: P×1.2
A9: Bear case 下行目標 | B9: 1500 | C9: =B9/Kevin模型!B22-1 | D9: EPS 76.9 × 19.5x
A10: FactSet 共識目標價（參考） | B10: 3500 | C10: =B10/Kevin模型!B22-1 | D10: 外部觀點，非本模型
A12: PEG（情境 A） | B12: =Kevin模型!B46 | D12: <1 🟢 偏便宜
A14: 本估算為 Kevin 個人模型試算，非投資建議。

Sheet 同業比較
A1: 同業比較（2026-10-01；TTM=2025Q3–2026Q2；比率為 2026H1）
A3: 公司 | B3: 代號 | C3: 可比類型 | D3: 幣別 | E3: 收盤價 | F3: 市值(億，原幣) | G3: TTM EPS | H3: PE TTM | I3: PB | J3: 毛利率 | K3: 淨利率 | L3: H1營收YoY | M3: 8月營收YoY | N3: 1–8月YoY | O3: Q2 EPS YoY
A4: 智邦 | B4: TWSE:2345 | C4: 目標 | D4: TWD | E4: 1900 | F4: 10619.252 | G4: 63.65 | H4: =E4/G4 | I4: 15.35456 | J4: 0.19632007 | K4: 0.11698335 | L4: 0.60288123 | M4: 0.594 | N4: 0.619 | O4: 1.1953385
A5: Celestica | B5: NYSE:CLS | C5: 完全可比 | D5: USD | E5: 372.25 | F5: 428.02049 | G5: 9.72 | H5: =E5/G5 | I5: 17.264377 | J5: 0.11602406 | K5: 0.066444841 | L5: 0.57805846 | M5: N/A | N5: N/A | O5: 0.75409836
A6: Arista Networks | B6: NYSE:ANET | C6: 替代可比 | D6: USD | E6: 204.385 | F6: 2573.5535 | G6: 3.21 | H6: =E6/G6 | I6: 17.387856 | J6: 0.62441903 | K6: 0.38919352 | L6: 0.36466648 | M6: N/A | N6: N/A | O6: 0.35211268
A7: 啟碁 | B7: TWSE:6285 | C7: 相鄰可比 | D7: TWD | E7: 235.5 | F7: 1139.0281 | G7: 9.2 | H7: =E7/G7 | I7: 3.1601714 | J7: 0.12956701 | K7: 0.040260448 | L7: 0.22802551 | M7: 0.8121 | N7: 0.3783 | O7: 2.2912621
A8: 同業中位數 | H8: =MEDIAN(H5:H7) | I8: =MEDIAN(I5:I7) | J8: =MEDIAN(J5:J7) | K8: =MEDIAN(K5:K7) | L8: =MEDIAN(L5:L7) | O8: =MEDIAN(O5:O7)
A9: 同業平均 | H9: =AVERAGE(H5:H7) | I9: =AVERAGE(I5:I7) | J9: =AVERAGE(J5:J7) | K9: =AVERAGE(K5:K7) | L9: =AVERAGE(L5:L7) | O9: =AVERAGE(O5:O7)
A11: RelPE_TTM | B11: =H4/H8 | C11: <0.85 偏低；0.85–1.15 合理；>1.15 偏高
A12: RelPE_FWD | B12: =Kevin模型!B22/Kevin模型!B37/H8 | C12: 現價÷模型EPS ÷ 同業TTM中位
A13: RelGM (pp) | B13: =(J4-J8)*100 | C13: 正值通常對應較高 PE
A14: Rel_RevGrowth (pp) | B14: =(L4-L8)*100 | C14: H1 營收 YoY 差
A15: 綜合判斷 | B15: =IF(AND(B11<0.85,B13>=0,B14>=0),"相對偏低估",IF(AND(B11>1.15,B13<=0,B14<=0),"相對偏高估","相對合理"))
A17: 來源：Bigdata.com company tearsheet（FMP，2026-10-01）；台股月營收：鉅亨網。美股無月營收標 N/A；營收成長統一用 2026H1 YoY。

Sheet Kevin模型
A1: 智邦（2345）Kevin 雙層錨定模型 資料日 2026-10-01（藍字可改）
A2: ⚠ provisional：MOPS/TWSE 被環境網路封鎖；財報取自 Kevin workbook 季報調節頁與 Bigdata.com(FMP)，月營收取自新聞彙整
A4: 項目 | B4: 數值 | C4: 單位 | D4: 資料來源
A5: 1–n月累計營收 E | B5: 246003583 | C5: 千元 | D5: workbook CPO概念頁 1-8月營收；新聞 2,460.04億
A6: 累計月數 n | B6: 8 | C6: 月 | D6: 1–8月
A7: H1 營收 | B7: 165658435 | C7: 千元 | D7: workbook 季報調節（2026H1）
A8: H1 稅前淨利 | B8: 24930070 | C8: 千元 | D8: plugin 測試案例/MOPS 2026H1
A9: H1 所得稅 | B9: 5549864 | C9: 千元 | D9: 同上
A10: H1 本期淨利（合併） | B10: 19380206 | C10: 千元 | D10: 同上（稅前−所得稅）
A11: 非經常性：匯兌 | B11: 132793 | C11: 千元 | D11: 同上
A12: 非經常性：股票評價 | B12: 5829 | C12: 千元 | D12: 同上
A13: 業主淨利占比 W | B13: 1 | C13: 倍 | D13: workbook（歸母÷合併≈100%）
A14: 股本 | B14: 5611179 | C14: 千元 | D14: 資產負債表普通股股本
A15: 面額 | B15: 10 | C15: 元
A16: 2025 EPS J | B16: 47.13 | C16: 元 | D16: 2025 年報（四季 9.17+9.01+14.00+14.95）
A17: ETF PE（00891） | B17: 28 | C17: 倍 | D17: workbook Anchor設定 2026/09/11
A18: ratio_P | B18: 0.85 | D18: CPO 類
A19: ratio_Q | B19: 0.62 | D19: CPO 類
A20: 大盤 PE | B20: 31.26 | C20: 倍 | D20: workbook（7/09 水位）
A21: 大盤 10 年中位 PE | B21: 17 | C21: 倍 | D21: workbook 粗估
A22: 目前股價 M | B22: 1900 | C22: 元 | D22: 2026-10-01 收盤（Bigdata.com/FMP）
A23: 7月營收 | B23: 39472565 | C23: 千元 | D23: 1–7月累計 − H1（新聞 394.73億）
A24: 8月營收 | B24: 40872583 | C24: 千元 | D24: 1–8月 − 1–7月（新聞 408.73億）
A25: Q2 合併淨利率（情境B） | B25: 0.115621 | D25: 2026Q2 淨利 110.47億 ÷ 營收 955.46億
A26: 目標價溢價 | B26: 1 | C26: 倍 | D26: 預設 1（只乘目標價）
A28: 計算
A29: 項目 | B29: 情境 A（累計年化） | C29: 情境 B（近月動能） | D29: 公式
A30: M 比值 | B30: =B20/B21 | C30: =B20/B21 | D30: 大盤PE÷10年中位
A31: M_adj | B31: =IF(B30>1.3,0.85,IF(B30<0.8,1.15,1)) | C31: =IF(C30>1.3,0.85,IF(C30<0.8,1.15,1)) | D31: M>1.3→0.85
A32: base_P | B32: =B17*B18*B31 | C32: =B17*B18*C31 | D32: ETF PE×ratio_P×M_adj
A33: base_Q | B33: =B17*B19*B31 | C33: =B17*B19*C31 | D33: ETF PE×ratio_Q×M_adj
A34: 非經常性占稅前 | B34: =ABS(B11+B12)/B8 | C34: =ABS(B11+B12)/B8 | D34: <5% 乾淨
A35: 淨利率 H（合併） | B35: =B10/B7 | C35: =B25 | D35: A：H1 帳面；B：Q2
A36: 年化營收 | B36: =B5*12/B6 | C36: =B5+(B23+B24)/2*(12-B6) | D36: 千元
A37: 預期 EPS N | B37: =B36*B35*B13/B14*B15 | C37: =C36*C35*B13/B14*B15 | D37: 年化營收×H×W÷股本×面額
A38: EPS 成長率 O | B38: =B37/B16-1 | C38: =C37/B16-1 | D38: N÷J−1
A39: PE_P | B39: =B32+SQRT(MAX(B38,0)*100) | C39: =C32+SQRT(MAX(C38,0)*100) | D39: base_P+√(O×100)
A40: PE_Q | B40: =B33+(MAX(B38,0)*100)^(2/3) | C40: =C33+(MAX(C38,0)*100)^(2/3) | D40: base_Q+(O×100)^(2/3)
A41: 股價 A | B41: =B37*B39 | C41: =C37*C39 | D41: N×PE_P
A42: 股價 B | B42: =B37*B40 | C42: =C37*C40 | D42: N×PE_Q
...

Sheet 季度財務
A1: 季度 | B1: 營收(百萬) | C1: 毛利(百萬) | D1: 毛利率 | E1: 營業利益(百萬) | F1: 營益率 | G1: 稅前(百萬) | H1: 業外占稅前 | I1: 歸母淨利(百萬) | J1: EPS | K1: 存貨(百萬) | L1: 營業現金流(百萬)
A2: 2024Q3 | B2: 28192.739 | C2: 5608.73 | D2: =C2/B2 | E2: 3463.45 | F2: =E2/B2 | G2: 3308.727 | H2: =(G2-E2)/G2 | I2: 2650.075 | J2: 4.75 | K2: 17807.319 | L2: 4995.68
A3: 2024Q4 | B3: 38971.903 | C3: 8064.689 | D3: =C3/B3 | E3: 5182.431 | F3: =E3/B3 | G3: 5659.005 | H3: =(G3-E3)/G3 | I3: 4524.904 | J3: 8.1 | K3: 19370.957 | L3: 3282.63
A4: 2025Q1 | B4: 42750.561 | C4: 8647.449 | D4: =C4/B4 | E4: 5947.219 | F4: =E4/B4 | G4: 6281.874 | H4: =(G4-E4)/G4 | I4: 5127.365 | J4: 9.17 | K4: 23945.208 | L4: 4077.598
A5: 2025Q2 | B5: 60604.798 | C5: 10863.942 | D5: =C5/B5 | E5: 8125.282 | F5: =E5/B5 | G5: 6613.117 | H5: =(G5-E5)/G5 | I5: 5031.753 | J5: 9.01 | K5: 26197.713 | L5: 2230.849
A6: 2025Q3 | B6: 72946.563 | C6: 12315.464 | D6: =C6/B6 | E6: 9000.71 | F6: =E6/B6 | G6: 9707.726 | H6: =(G6-E6)/G6 | I6: 7826.6 | J6: 14 | K6: 31886.348 | L6: 18714.525
A7: 2025Q4 | B7: 72070.726 | C7: 12909.713 | D7: =C7/B7 | E7: 9165.175 | F7: =E7/B7 | G7: 10314.141 | H7: =(G7-E7)/G7 | I7: 8347.911 | J7: 14.95 | K7: 30201.828 | L7: 10088.526
A8: 2026Q1 | B8: 70120.741 | C8: 13700.875 | D8: =C8/B8 | E8: 10048.687 | F8: =E8/B8 | G8: 10361.703 | H8: =(G8-E8)/G8 | I8: 8333.109 | J8: 14.92 | K8: 50479.738 | L8: -3388.226
A9: 2026Q2 | B9: 95545.624 | C9: 18822.758 | D9: =C9/B9 | E9: 14331.32 | F9: =E9/B9 | G9: 14568.367 | H9: =(G9-E9)/G9 | I9: 11047.097 | J9: 19.78 | K9: 76972.916 | L9: -11532.764
A11: 來源：Bigdata.com company tearsheet（provider FMP），2026-10-01 取用；未經 MOPS 原檔逐項核對。2025Q2 業外為負（台幣急升匯損），2025 全年業外占稅前約 +2%，故基期 EPS 不調整。

Sheet 來源與缺口
A1: 類型 | B1: 內容
A2: 來源 | B2: Bigdata.com 公司 tearsheet（FMP）
A3: 來源 | B3: Kevin workbook 投資組合_2026_09_11_updated.xlsx（Google Drive）
A4: 來源 | B4: 鉅亨網/經濟日報 7–8月營收新聞
A5: 來源 | B5: FactSet 共識（永豐金/鉅亨轉載）
A6: 來源 | B6: 工商時報（凱基、外資報告）
A7: 來源 | B7: Celestica FY2025 10-K
A8: 缺口 | B8: 官方身分查核（MOPS 公司基本資料）
A9: 缺口 | B9: MOPS 2026Q2 財報原檔逐項核對（已用 workbook 季報調節頁與 FMP 交叉）
A10: 缺口 | B10: 9月營收（10/10 前公告）
A11: 缺口 | B11: Q2 法說會逐字稿/簡報（Bigdata 未收錄）
A12: 缺口 | B12: 同業估值數字
A13: 缺口 | B13: 大盤 PE 最新值（workbook 取 7/09 水位）
